Workbook

Sheet Pivot Table
A3: Row Labels | B3: Count of UserID
A4: Unlisted | B4: 218
A5: Eastern Cape | B5: 287
A6: Free State | B6: 156
A7: Gauteng | B7: 1704
A8: Kwazulu Natal | B8: 481
A9: Limpopo | B9: 368
A10: Mpumalanga | B10: 421
A11: None | B11: 702
A12: North West | B12: 161
A13: Northern Cape | B13: 86
A14: Western Cape | B14: 791
A15: Grand Total | B15: 5375

Sheet User Profiles
A1: UserID | B1: Name | C1: Surname | D1: Email | E1: Gender | F1: Race | G1: Age | H1: Province | I1: Social Media Handle
A2: 34 | B2: Chas | C2: Biggers | D2: Chas 351@yahoo.com | E2: male | F2: white | G2: 55 | H2: Free State | I2: @Chas 35
A3: 39 | B3: Wilburn | C3: Crotty | D3: Wilburn 303@mail.com | E3: male | F3: black | G3: 54 | H3: Eastern Cape | I3: @Wilburn 30
A4: 63 | B4: Emerson | C4: Slane | D4: Emerson 243@mail.com | E4: male | F4: black | G4: 51 | H4: Kwazulu Natal | I4: @Emerson 24
A5: 90 | B5: Stacy | C5: Sytsma | D5: Stacy 273@mail.com | E5: male | F5: coloured | G5: 49 | H5: Kwazulu Natal | I5: @Stacy 27
A6: 97 | B6: Lucas | C6: Woolard | D6: Lucas 233@mail.com | E6: male | F6: coloured | G6: 48 | H6: Free State | I6: @Lucas 23
A7: 104 | B7: Randy | C7: Tancredi | D7: Randy 393@mail.com | E7: male | F7: black | G7: 47 | H7: Gauteng | I7: @Randy 39
A8: 107 | B8: Trudie | C8: Restivo | D8: Trudie 502@gmail.com | E8: female | F8: black | G8: 47 | H8: Gauteng | I8: @Trudie 50
A9: 108 | B9: Chas | C9: Luthy | D9: Chas 352@gmail.com | E9: male | F9: coloured | G9: 47 | H9: Western Cape | I9: @Chas 35
A10: 120 | B10: Jared | C10: Bilyeu | D10: Jared 503@mail.com | E10: male | F10: coloured | G10: 46 | H10: Western Cape | I10: @Jared 50
A11: 132 | B11: Carter | C11: Wigfall | D11: Carter 33@mail.com | E11: male | F11: black | G11: 45 | H11: Gauteng | I11: @Carter 3
A12: 135 | B12: Emerson | C12: Beville | D12: Emerson 241@yahoo.com | E12: male | F12: other | G12: 45 | H12: Gauteng | I12: @Emerson 24
A13: 138 | B13: Abel | C13: Hier | D13: Abel 185@mailxyz.com | E13: male | F13: None | G13: 45 | H13: Eastern Cape | I13: @Abel 18
... A4322: 1133250 | B4322: Wilburn | C4322: Bilyeu | D4322: Wilburn 304@abcmail.com | E4322: male | F4322: indian_asian | G4322: 36 | H4322: Gauteng | I4322: @Wilburn 30
A4323: 1280861 | B4323: None | C4323: None | D4323: Williemae 254@abcmail.com | G4323: 0 | I4323: None
A4324: 1281997 | B4324: Carlota | C4324: Tancredi | D4324: Carlota 273@mail.com | E4324: female | F4324: coloured | G4324: 14 | H4324: Free State | I4324: @Carlota 27
A4325: 1283498 | B4325: None | C4325: None | D4325: Briana 62@gmail.com | G4325: 0 | I4325: None
A4326: 1285704 | B4326: None | C4326: None | D4326: Rebekah 464@abcmail.com | G4326: 0 | I4326: None
A4327: 1285929 | B4327: None | C4327: None | D4327: Lesli 65@mailxyz.com | G4327: 0 | I4327: None
A4328: 1285950 | B4328: Jared | C4328: Crotty | D4328: Jared 505@mailxyz.com | E4328: male | F4328: coloured | G4328: 30 | H4328: Mpumalanga | I4328: @Jared 50
A4329: 1287933 | B4329: Kip | C4329: Arrieta | D4329: Kip 142@gmail.com | E4329: male | F4329: white | G4329: 26 | H4329: Northern Cape | I4329: @Kip 14
A4330: 1292142 | B4330: None | C4330: None | D4330: Epifania 43@mail.com | G4330: 0 | I4330: None
A4331: 1293485 | B4331: Lane | C4331: Wigfall | D4331: Lane 113@mail.com | E4331: male | F4331: black | G4331: 21 | H4331: Gauteng | I4331: @Lane 11
A4332: 1295130 | B4332: None | C4332: None | D4332: Dia 343@mail.com | G4332: 0 | I4332: None
A4333: 1297394 | B4333: None | C4333: None | D4333: Nubia 375@mailxyz.com | G4333: 0 | I4333: None
A4334: 1298176 | B4334: None | C4334: None | D4334: Lesli 405@mailxyz.com | G4334: 0 | I4334: None
A4335: 1299853 | B4335: Rebecka | C4335: Shkreli | D4335: Rebecka 313@mail.com | E4335: female | F4335: black | G4335: 22 | H4335: North West | I4335: @Rebecka 31
A4336: 1303457 | B4336: None | C4336: None | D4336: Mellie 394@abcmail.com | G4336: 0 | I4336: None
A4337: 1304008 | B4337: None | C4337: None | D4337: Bess 61@yahoo.com | G4337: 0 | I4337: None
A4338: 1307720 | B4338: None | C4338: None | D4338: Lillian 95@mailxyz.com | G4338: 0 | I4338: None
A4339: 1308689 | B4339: None | C4339: None | D4339: Tiffani 383@mail.com | G4339: 0 | I4339: None
A4340: 1310414 | B4340: None | C4340: None | D4340: Nubia 483@mail.com | G4340: 0 | I4340: None
A4341: 1310589 | B4341: Michel | C4341: Langenfeld | D4341: Michel 203@mail.com | E4341: male | F4341: black | G4341: 33 | H4341: Mpumalanga | I4341: @Michel 20
A4342: 1312534 | B4342: None | C4342: None | D4342: Trudie 44@abcmail.com | G4342: 0 | I4342: None
A4343: 1314312 | B4343: None | C4343: None | D4343: Nakita 462@gmail.com | G4343: 0 | I4343: None
A4344: 1315326 | B4344: None | C4344: None | D4344: Yolonda 365@mailxyz.com | G4344: 0 | I4344: None
A4345: 1316622 | B4345: None | C4345: None | D4345: Gretta 155@mailxyz.com | G4345: 0 | I4345: None
A4346: 1318133 | B4346: Romeo | C4346: Restivo | D4346: Romeo 372@gmail.com | E4346: male | F4346: other | G4346: 17 | H4346: Kwazulu Natal | I4346: @Romeo 37
A4347: 1319265 | B4347: None | C4347: None | D4347: Seema 105@mailxyz.com | G4347: 0 | I4347: None
A4348: 1320407 | B4348: None | C4348: None | D4348: Iva 15@mailxyz.com | G4348: 0 | I4348: None
...

Sheet Channel Analysis
A3: Row Labels | B3: Sum of Duration 2 | G3: Row Labels | H3: Count of Channel2
A4: E! Entertainment | B4: 1.5410185 | G4: E! Entertainment | H4: 367
A5: Africa Magic | B5: 2.0326505 | G5: CNN | H5: 505
A6: CNN | B6: 2.8240625 | G6: Boomerang | H6: 714
A7: Cartoon Network | B7: 2.9272801 | G7: Cartoon Network | H7: 793
A8: Boomerang | B8: 3.0524653 | G8: Africa Magic | H8: 859
A9: SuperSport Blitz | B9: 3.7783102 | G9: SuperSport Blitz | H9: 896
A10: Trace TV | B10: 7.9968403 | G10: Trace TV | H10: 952
A11: Channel O | B11: 8.0314931 | G11: Channel O | H11: 1050
A12: Supersport Live Events | B12: 13.065718 | G12: ICC Cricket World Cup 2011 | H12: 1465
A13: ICC Cricket World Cup 2011 | B13: 17.171898 | G13: Supersport Live Events | H13: 1662
A14: Grand Total | B14: 62.421736 | G14: Grand Total | H14: 9263

Sheet Sheet9
A3: Row Labels | B3: Count of Day2
A4: Friday | B4: 1435
A5: Monday | B5: 1363
A6: Saturday | B6: 1570
A7: Sunday | B7: 1354
A8: Thursday | B8: 1379
A9: Tuesday | B9: 1539
A10: Wednesday | B10: 1360
A11: Grand Total | B11: 10000

Sheet Sheet14
A3: Row Labels | B3: Count of UserID
A4: 0 | B4: 80
A5: 1 | B5: 55
A6: 2 | B6: 49
A7: 3 | B7: 94
A8: 4 | B8: 180
A9: 5 | B9: 298
A10: 6 | B10: 401
A11: 7 | B11: 402
A12: 8 | B12: 541
A13: 9 | B13: 539
A14: 10 | B14: 634
A15: 11 | B15: 568
... A27: 23 | B27: 103
A28: Grand Total | B28: 10000

Sheet Sheet5
A1: Day2 | B1: Monday
A3: Row Labels | B3: Count of Channel2
A4: Africa Magic | B4: 0.10431373
A5: Boomerang | B5: 0.080784314
A6: Cartoon Network | B6: 0.098039216
A7: Channel O | B7: 0.12078431
A8: CNN | B8: 0.05254902
A9: E! Entertainment | B9: 0.03372549
A10: ICC Cricket World Cup 2011 | B10: 0.14431373
A11: SuperSport Blitz | B11: 0.090196078
A12: Supersport Live Events | B12: 0.16784314
A13: Trace TV | B13: 0.10745098
A14: Grand Total | B14: 1

Sheet Viewership
A1: UserID | B1: Channel2 | C1: RecordDate2 | D1: Duration 2 | E1: userid2 | F1: Date | G1: Time | H1: Day2 | I1: Hours
A2: 866344 | B2: ICC Cricket World Cup 2011 | C2: 42441.613 | D2: 0.4787963 | E2: 866344 | F2: 42441 | G2: 14:42:00 | H2: =TEXT(A2,"dddd") -> Tuesday | I2: =HOUR(G2) -> 14
A3: 2285790 | B3: CNN | C3: 42403.578 | D3: 0.30858796 | E3: 2285790 | F3: 42403 | G3: 13:52:00 | H3: =TEXT(A3,"dddd") -> Tuesday | I3: =HOUR(G3) -> 13
A4: 892453 | B4: ICC Cricket World Cup 2011 | C4: 42455.648 | D4: 0.20916667 | E4: 892453 | F4: 42455 | G4: 15:33:00 | H4: =TEXT(A4,"dddd") -> Monday | I4: =HOUR(G4) -> 15
A5: 771927 | B5: Supersport Live Events | C5: 42401.342 | D5: 0.20069444 | E5: 771927 | F5: 42401 | G5: 08:12:00 | H5: =TEXT(A5,"dddd") -> Monday | I5: =HOUR(G5) -> 8
A6: 861217 | B6: ICC Cricket World Cup 2011 | C6: 42455.563 | D6: 0.19180556 | E6: 861217 | F6: 42455 | G6: 13:31:00 | H6: =TEXT(A6,"dddd") -> Saturday | I6: =HOUR(G6) -> 13
A7: 810175 | B7: Channel O | C7: 42410.897 | D7: 0.17902778 | E7: 810175 | F7: 42410 | G7: 21:32:00 | H7: =TEXT(A7,"dddd") -> Monday | I7: =HOUR(G7) -> 21
A8: 822212 | B8: Supersport Live Events | C8: 42426.799 | D8: 0.17414352 | E8: 822212 | F8: 42426 | G8: 19:10:00 | H8: =TEXT(A8,"dddd") -> Friday | I8: =HOUR(G8) -> 19
A9: 2369790 | B9: ICC Cricket World Cup 2011 | C9: 42419.623 | D9: 0.16905093 | E9: 2369790 | F9: 42419 | G9: 14:57:00 | H9: =TEXT(A9,"dddd") -> Tuesday | I9: =HOUR(G9) -> 14
A10: 2288446 | B10: Trace TV | C10: 42423.364 | D10: 0.1559375 | E10: 2288446 | F10: 42423 | G10: 08:44:00 | H10: =TEXT(A10,"dddd") -> Friday | I10: =HOUR(G10) -> 8
A11: 794368 | B11: Supersport Live Events | C11: 42419.757 | D11: 0.15194444 | E11: 794368 | F11: 42419 | G11: 18:10:00 | H11: =TEXT(A11,"dddd") -> Sunday | I11: =HOUR(G11) -> 18
A12: 789082 | B12: Supersport Live Events | C12: 42416.899 | D12: 0.15016204 | E12: 789082 | F12: 42416 | G12: 21:35:00 | H12: =TEXT(A12,"dddd") -> Saturday | I12: =HOUR(G12) -> 21
A13: 892643 | B13: Boomerang | C13: 42371.017 | D13: 0.14746528 | E13: 892643 | F13: 42371 | G13: 00:24:00 | H13: =TEXT(A13,"dddd") -> Tuesday | I13: =HOUR(G13) -> 0
... A10001: 805381 | B10001: Supersport Live Events | C10001: 42433.32 | D10001: 0 | E10001: 805381 | F10001: 42433 | G10001: 07:41:00 | H10001: =TEXT(A10001,"dddd") -> Tuesday | I10001: =HOUR(G10001) -> 7

Sheet Summary
A1: Metric | B1: Value | H1: Province Breakdown
A2: Total Registered Users | B2: =COUNTA('User Profiles'!A:A)-1 -> 5375 | H2: Row Labels | I2: Count of UserID
A3: Active Users (watched content) | B3: {=SUMPRODUCT((COUNTIF(Viewership!A:A,'User Profiles'!A2:A5376)>0)*1)} -> 4386 | I3: 218
A4: Total Sessions | B4: =COUNTA(Viewership!A:A)-1 -> 10000 | H4: Eastern Cape | I4: 287
A5: Unique Channels | B5: {=SUMPRODUCT(1/COUNTIF(Viewership!B2:B10001,Viewership!B2:B10001))} -> 19 | H5: Free State | I5: 156
H6: Gauteng | I6: 1704
A7: Female Users | B7: =COUNTIF('User Profiles'!E:E,"female") -> 537 | H7: Kwazulu Natal | I7: 481
A8: Male Users | B8: =COUNTIF('User Profiles'!E:E,"male") -> 3918 | H8: Limpopo | I8: 368
H9: Mpumalanga | I9: 421
A10: Province Breakdown | H10: None | I10: 702
H11: North West | I11: 161
H12: Northern Cape | I12: 86
H13: Western Cape | I13: 791
H14: Grand Total | I14: 5375
A15: Age Group | B15: Count
A16: Under 18 | B16: =COUNTIF('User Profiles'!G:G,"<18") -> 1044
A17: 18–34 | B17: =COUNTIFS('User Profiles'!G:G,">="&18,'User Profiles'!G:G,"<="&34) -> 2532
A18: 35–44 | B18: =COUNTIFS('User Profiles'!G:G,">="&35,'User Profiles'!G:G,"<="&44) -> 1215
A19: 45–55 | B19: =COUNTIFS('User Profiles'!G:G,">="&45,'User Profiles'!G:G,"<="&55) -> 471
A20: 55+ | B20: =COUNTIF('User Profiles'!G:G, ">= 55") -> 130
A22: January Sessions | B22: =COUNTIFS(Viewership!C:C,">="&DATE(2016,1,1),Viewership!C:C,"<="&DATE(2016,1,31)) -> 2147
A23: February Sessions | B23: =COUNTIFS(Viewership!C:C,">="&DATE(2016,2,1),Viewership!C:C,"<="&DATE(2016,2,29)) -> 2976
A24: March Sessions | B24: =COUNTIFS(Viewership!C:C,">="&DATE(2016,3,1),Viewership!C:C,"<="&DATE(2016,3,31)) -> 4693
A26: Avg Session Duration (days) | B26: =AVERAGE(Viewership!D:D) -> 0.0063461088
A27: Avg Session Duration (minutes) | B27: =B26*24*60 -> 9.1383967
